<mujoco model="Bipedal">
  <option iterations="50" timestep="0.001" solver="PGS" gravity="0 0 -9.81" />

  <compiler angle="radian"  eulerseq="zyx" autolimits="true" />

  <default>
    <joint limited="true" damping="0.01" armature="0.01" frictionloss="0.01" />
    <geom condim="3" contype="1" conaffinity="15" friction="1.8 0.05 0.001" solref="0.02 1" solimp="0.9 0.95 0.001" />
    <position ctrllimited="true" />
    <equality solref="0.001 2" />
    <default class="visualgeom">
      <geom material="visualgeom" condim="1" contype="0" conaffinity="0" />
    </default>
  </default>

  <asset>
    <mesh name="base_link" content_type="model/stl" file="base_link.STL" />
    <mesh name="left_hip_link" content_type="model/stl" file="left_hip_link.STL" />
    <mesh name="left_knee_link" content_type="model/stl" file="left_knee_link.STL" />
    <mesh name="right_hip_link" content_type="model/stl" file="right_hip_link.STL" />
    <mesh name="right_knee_link" content_type="model/stl" file="right_knee_link.STL" />
    <mesh name="left_wheel_link" content_type="model/stl" file="left_wheel_link.STL" />
    <mesh name="right_wheel_link" content_type="model/stl" file="right_wheel_link.STL" />
    <texture name="texplane" type="2d" builtin="checker" rgb1=".0 .0 .0" rgb2=".8 .8 .8" width="100" height="100" />
    <material name="matplane" reflectance="0." texture="texplane" texrepeat="1 1" texuniform="true" />
    <material name="visualgeom" rgba="0.5 0.9 0.2 1" />
  </asset>

  <worldbody>
    <light directional="true" diffuse="0.4 0.4 0.4" specular="0.1 0.1 0.1" pos="0 0 5.0" dir="0 0 -1" castshadow="false" />
    <light directional="true" diffuse="0.6 0.6 0.6" specular="0.2 0.2 0.2" pos="0 0 4" dir="0 0 -1" />
    <geom name="ground" type="plane" pos="0 0 0" size="100 100 0.001" quat="1 0 0 0" material="matplane" condim="3" conaffinity="15" />
    <camera name="fixed" pos="0 -3.0 0.9730745173996977" xyaxes="1 0 0 0 0 1" />
    <camera name="track" mode="trackcom" pos="0 -3.0 0.9730745173996977" xyaxes="1 0 0 0 0 1" />
    <body name="root" pos="0 0 0.547307451739969775" quat="1 0 0 0">
      <freejoint name="root" />
      <inertial  pos="0.01 -0.0196003228135452 -0.0227358081145863" mass="2.58680345236989" fullinertia="0.0215162702470085 0.02233115289391 0.0214719602558426 -5.17133997903683e-06 -4.56150022793563e-06 2.30329361555432e-05"/>
      <site name="imu" size="0.01" pos="0 0 0" />
      <geom type="mesh" rgba="1 1 1 1" mesh="base_link" contype="1" conaffinity="0" density="0" group="1" class="visualgeom" />
      <geom type="mesh" rgba="1 1 1 1" mesh="base_link" />
      <body name="left_hip_link" pos="0.00888 0.07579 -0.053421" quat="0.00385111 0.707095 0.707098 0.00385112">
        <inertial pos="0.0221476 -0.00180782 0.0832383" quat="0.999941 0.0108585 0.000319679 9.90337e-06" mass="0.548021" diaginertia="0.00300532 0.00292396 0.000248069" />
        <joint name="left_hip" pos="0 0 0" axis="-1 0 0" range="-1.57 1.57" actuatorfrcrange="-8 8" damping="0.56"/>
        <geom type="mesh" rgba="1 1 1 1" mesh="left_hip_link" contype="1" conaffinity="0" density="0" group="1" class="visualgeom" />
        <geom type="mesh" rgba="1 1 1 1" mesh="left_hip_link" />
        <body name="left_knee_link" pos="0.011886 -0.0043428 0.19995" quat="0.99984 0.017892 0 0">
          <inertial pos="0.01 0.00405816 0.0780025" quat="0.999683 -0.0251816 0 0" mass="0.235606" diaginertia="0.00125058 0.00120796 5.83331e-05" />
          <joint name="left_knee" pos="0 0 0" axis="-1 0 0" range="-2.51 2.51" actuatorfrcrange="-4 4" damping="0.56" />
          <geom type="mesh" rgba="1 1 1 1" mesh="left_knee_link" contype="1" conaffinity="0" density="0" group="1" class="visualgeom" />
          <geom type="mesh" rgba="1 1 1 1" mesh="left_knee_link" />
          <body name="left_wheel_link" pos="0 0.0099672 0.19975" quat="0.849056 0.528302 0 0">
            <inertial pos="0.0398848 0 0" mass="0.511294" diaginertia="0.00206123 0.00104922 0.00104922" />
            <joint name="left_wheel" pos="0 0 0" axis="1 0 0" actuatorfrcrange="-2 2" limited="true" range="-1000000 1000000" damping="0.12"/>
            <geom type="mesh" rgba="0.792157 0.819608 0.933333 1" mesh="left_wheel_link" contype="1" conaffinity="0" density="0" group="1" class="visualgeom" />
            <geom type="mesh" rgba="0.792157 0.819608 0.933333 1" mesh="left_wheel_link" />
          </body>
        </body>
      </body>
      <body name="right_hip_link" pos="0.00888 -0.12044 -0.053421" quat="0.0134669 -0.706977 0.70698 -0.013467">
        <inertial pos="0.0221476 5.51885e-08 0.0832579" quat="1 7.78778e-07 0.000319768 6.4318e-06" mass="0.548021" diaginertia="0.00300532 0.00292396 0.000248069" />
        <joint name="right_hip" pos="0 0 0" axis="1 0 0" range="-1.57 1.57" actuatorfrcrange="-8 8" damping="0.56"/>
        <geom type="mesh" rgba="1 1 1 1" mesh="right_hip_link" contype="1" conaffinity="0" density="0" group="1" class="visualgeom" />
        <geom type="mesh" rgba="1 1 1 1" mesh="right_hip_link" />
        <body name="right_knee_link" pos="0.011886 0 0.2" quat="-3.67311e-06 -2.59051e-08 0.00705244 0.999975">
          <inertial pos="-0.01 -0.00358343 0.0780258" quat="0.999718 0.0237501 0 0" mass="0.235606" diaginertia="0.00125058 0.00120796 5.83331e-05" />
          <joint name="right_knee" pos="0 0 0" axis="-1 0 0" range="-2.51 2.51" actuatorfrcrange="-4 4" damping="0.56" />
          <geom type="mesh" rgba="1 1 1 1" mesh="right_knee_link" contype="1" conaffinity="0" density="0" group="1" class="visualgeom" />
          <geom type="mesh" rgba="1 1 1 1" mesh="right_knee_link" />
          <body name="right_wheel_link" pos="0 -0.0095996 0.19977" quat="-3.58152e-06 8.15558e-07 -0.222029 0.97504">
            <inertial pos="0.0398848 0 0" mass="0.511294" diaginertia="0.00206123 0.00104922 0.00104922" />
            <joint name="right_wheel" pos="0 0 0" axis="-1 0 0" actuatorfrcrange="-2 2" limited="true" range="-1000000 1000000" damping="0.12" />
            <geom type="mesh" rgba="0.792157 0.819608 0.933333 1" mesh="right_wheel_link" contype="1" conaffinity="0" density="0" group="1" class="visualgeom" />
            <geom type="mesh" rgba="0.792157 0.819608 0.933333 1" mesh="right_wheel_link" />
          </body>
        </body>
      </body>
    </body>
  </worldbody>

  <actuator>
    <position name="left_hip" joint="left_hip" ctrllimited="true" kp="5" ctrlrange="-8 8" gear="1" />
    <position name="left_knee" joint="left_knee" ctrllimited="true" kp="5"  ctrlrange="-4 4" gear="1" />
    <velocity name="left_wheel" joint="left_wheel" ctrllimited="true"   ctrlrange="-2 2" gear="1" />
    <position name="right_hip" joint="right_hip" ctrllimited="true" kp="5"  ctrlrange="-8 8" gear="1" />
    <position name="right_knee" joint="right_knee" ctrllimited="true" kp="5"  ctrlrange="-4 4" gear="1" />
    <velocity name="right_wheel" joint="right_wheel" ctrllimited="true" ctrlrange="-2 2" gear="1" />
  </actuator>

  <sensor>
    <actuatorpos name="left_hip_p" actuator="left_hip" />
    <actuatorvel name="left_hip_v" actuator="left_hip" />
    <actuatorfrc name="left_hip_f" actuator="left_hip" noise="0.001" />
    <actuatorpos name="left_knee_p" actuator="left_knee" />
    <actuatorvel name="left_knee_v" actuator="left_knee" />
    <actuatorfrc name="left_knee_f" actuator="left_knee" noise="0.001" />
    <actuatorpos name="left_wheel_p" actuator="left_wheel" />
    <actuatorvel name="left_wheel_v" actuator="left_wheel" />
    <actuatorfrc name="left_wheel_f" actuator="left_wheel" noise="0.001" />
    <actuatorpos name="right_hip_p" actuator="right_hip" />
    <actuatorvel name="right_hip_v" actuator="right_hip" />
    <actuatorfrc name="right_hip_f" actuator="right_hip" noise="0.001" />
    <actuatorpos name="right_knee_p" actuator="right_knee" />
    <actuatorvel name="right_knee_v" actuator="right_knee" />
    <actuatorfrc name="right_knee_f" actuator="right_knee" noise="0.001" />
    <actuatorpos name="right_wheel_p" actuator="right_wheel" />
    <actuatorvel name="right_wheel_v" actuator="right_wheel" />
    <actuatorfrc name="right_wheel_f" actuator="right_wheel" noise="0.001" />
    
    <framequat name="orientation" objtype="site" noise="0.001" objname="imu" />
    <gyro name="angular_velocity" site="imu"  noise="0.005" cutoff="34.9"/>
    <velocimeter name="linear_velocity" site="imu" noise="0.005" cutoff="34.9"/>
  </sensor>
</mujoco>